Workbook

Sheet DASHBOARD
B2: 📊 DASHBOARD ARMEDIA NET GUMELAR
B3: ="Update otomatis: "&TEXT(NOW(),"DD MMMM YYYY, HH:MM") -> Update otomatis: 20 Juli 2026, 11:22
B5: 👥 PELANGGAN AKTIF | D5: 💰 PENDAPATAN BULAN INI | F5: 🎁 DANA CSR | H5: 📦 SISA STOK ONT
B6: =COUNTIF('2_Data_Pelanggan'!$W$5:$W$500,"Aktif") -> 178 | D6: {=INDEX('10_Tagihan_Bulanan'!$F$208:$Q$208,1,MONTH(NOW()))} -> 15569418 | F6: ='5_Rekap_CSR'!D160 -> 390000 | H6: ='3_Perangkat'!C4 -> 128
B8: ="🔴 "&COUNTIF('2_Data_Pelanggan'!$W$5:$W$500,"Berhenti")&" berhenti" -> 🔴 3 berhenti | D8: =CHOOSE(MONTH(NOW()),"Januari","Februari","Maret","April","Mei","Juni","Juli","Agustus","September","Oktober","November","Desember") -> Juli | F8: Belum dicairkan | H8: unit tersedia
B11: 🚨 GANGGUAN JARINGAN | G11: 📋 PERLU TINDAKAN
B12: =COUNTIFS('9_Monitoring_Netwatch'!$C$4:$C$300,"DOWN",'9_Monitoring_Netwatch'!$E$4:$E$300,"?*")&" pelanggan sedang OFFLINE" -> 9 pelanggan sedang OFFLINE | G12: =SUMPRODUCT(('2_Data_Pelanggan'!$D$5:$D$500<>"")*(('2_Data_Pelanggan'!$I$5:$I$500="")+('2_Data_Pelanggan'!$J$5:$J$500="")>0))&" — RW/RT kosong" -> 16 — RW/RT kosong
B13: Cek sheet 9_Monitoring_Netwatch, gunakan link WA Follow Up Gangguan | G13: =COUNTIFS('2_Data_Pelanggan'!$D$5:$D$500,"<>",'2_Data_Pelanggan'!$E$5:$E$500,"")&" — NIK kosong" -> 34 — NIK kosong
G14: =COUNTIF('5_Rekap_CSR'!$Z$3:$Z$141,"Belum Dibayar")&" — RT Dana CSR belum cair" -> 139 — RT Dana CSR belum cair

Sheet 0_Panduan
B2: PANDUAN STRUKTUR DATABASE ARMEDIA
B3: Klik nama sheet di kolom kiri untuk langsung berpindah ke sheet tersebut
B6: SHEET | C6: PERAN & ALUR DATA
B7: 1_Calon_Pelanggan | C7: Daftar pendaftar BARU (PSB = Pasang Sambungan Baru). Belum tentu terpasang. Kolom "Status" menandai sudah Terpasang atau belum. Setelah terpasang & dapat ID Pelanggan (format G-xxxxxxx), data lengkapnya WAJIB dipindah/dicatat di sheet "2_Data_Pelanggan".
B8: 2_Data_Pelanggan | C8: SHEET MASTER / ACUAN UTAMA. Semua pelanggan yang sudah terpasang & aktif berlangganan dicatat lengkap di sini: identitas, alamat (Kec/Desa/RW/RT), paket, perangkat, status, link foto, lokasi & WhatsApp. Sheet lain (Rekap CSR) mengambil data dari sini secara otomatis via formula.
B9: ARSIP_Data_Teknis_Lama | C9: Data teknis versi LAMA. Sebagian isinya sudah terduplikasi dengan "2_Data_Pelanggan". Jangan diisi data baru di sini — gunakan "2_Data_Pelanggan" sebagai acuan utama. Sheet ini akan digabung/dirapikan saat proses input ulang data.
B10: 3_Perangkat | C10: Daftar inventaris perangkat ONT (nomor seri) yang terpasang. Terhubung ke "2_Data_Pelanggan" lewat kolom ID Perangkat.
B11: 4_Produk | C11: Daftar referensi paket & harga (ARMED 10-100, HEROIK 10-150). Dipakai sebagai acuan Paket & Harga otomatis di "2_Data_Pelanggan" lewat VLOOKUP.
B12: 5_Rekap_CSR | C12: Rekap otomatis dana CSR (Rp3.000/pelanggan/bulan, dibagi Desa Rp1.000 & RT Rp2.000). Dihitung otomatis dari "2_Data_Pelanggan" — TIDAK perlu diisi manual.
B13: 6_Marketing | C13: Pencatatan fee untuk mitra/marketing per pelanggan yang mereka referensikan.
B14: 8_Master_ODP | C14: Daftar kapasitas & pemakaian tiap titik ODP (15 titik, hasil ekstrak dari data lama). Kolom Kapasitas Maks & Desa/Lokasi masih perlu dilengkapi tim teknisi.
B15: 9_Monitoring_Netwatch | C15: Paste data export Netwatch Mikrotik (IP + Status) di kolom kuning — otomatis cocok ke pelanggan (Nama, Desa, RW/RT, WA) via pencarian IP di Data Pelanggan.
B16: 10_Tagihan_Bulanan | C16: Riwayat pembayaran tiap pelanggan per bulan (Jan-Des). ID/Nama/Paket otomatis dari 2_Data_Pelanggan; angka pembayaran diisi manual. Kolom bulan berjalan otomatis ter-highlight.
B17: 11_Slip_Gaji
B18: Tabel_ProRata | C18: Acuan cepat tagihan bulan pertama (pro-rata) untuk 8 paket ARMED, tanggal 1-30. Otomatis dari harga di 4_Produk.
B19: Registrasi_OLT | C19: Generator perintah registrasi OLT (ZTE GPON) + Netwatch Mikrotik. Ketik ID pelanggan, perintah CLI otomatis siap copy-paste. Lengkapi Port & Index di Data Pelanggan dulu.
B20: ⚠ CATATAN PENTING
B21: Ada kemungkinan data duplikat (nama/HP sama tercatat 2x) yang belum diverifikasi manual — akan dibenahi saat proses input ulang data lapangan.
B23: 📋 TEMPLATE PESAN WA — Minta Data RT/RW Pelanggan
B24: Selamat siang Bapak/Ibu [Nama Pelanggan], Mohon maaf mengganggu waktunya. Saya dari Tim Teknis Armedia Net wilayah Gumelar ingin melakukan pendataan ulang wilayah pelanggan. Boleh dibantu informasinya untuk posisi rumahnya di Cihonje masuk: RT berapa: RW berapa: Terima kasih banyak sebelumnya atas kerjasamanya.
B25: Catatan: ganti [Nama Pelanggan] sesuai penerima. Cocok dipakai untuk 14 pelanggan Cihonje yang RT/RW-nya masih kosong (lihat daftar di chat).
B28: ALUR CALON → PELANGGAN (manual)
B29: 1. Input calon | C29: Isi di sheet 1_Calon_Pelanggan (kolom kuning). NO & dropdown Status/Layanan otomatis.
B30: 2. Update status | C30: Saat proses: ganti Status (Belum → Survey → Jadwal → Aktif) lewat dropdown.
B31: 3. Sudah terpasang? | C31: Buka sheet 2_Data_Pelanggan, ke baris kosong pertama (kuning). Ketik: Nama, Produk ID (AR-2 dst), No.HP, Desa, RW, RT, Tgl Aktif. Sisanya (ID, Paket, Harga, Pro-rata, Profile) MUNCUL OTOMATIS.
B32: 4. Lengkapi teknis | C32: Isi IP, SN, ODP, Port OLT, Index, Redaman di Data Pelanggan.
B33: 5. Hapus dari calon | C33: Kembali ke 1_Calon_Pelanggan, klik kanan baris calon tadi > Hapus baris. Selesai.
B34: CATATAN | C34: Menu ARMEDIA cuma muncul di Google Sheets versi KOMPUTER, tidak di HP. Pemindahan dilakukan dari laptop.
B36: 12_ONT_NEW | C36: Inventaris ONT baru/stok (SN, MAC, SSID, status terpakai/belum, teknisi).
B37: 13_ONT_EROR | C37: Daftar ONT error/retur dari pelanggan (SN, keterangan kerusakan).
B38: 14_OPR | C38: Catatan biaya operasional (pembelian kabel, konektor, dll).
B40: PENANDA AUDIT DATA
B41: Merah (IP/SN) | C41: IP atau SN kembar - cek mana yang benar (arahkan kursor ke sel utk detail)
B42: Kuning (Nama) | C42: Kemungkinan pelanggan dobel - cek apakah orang yang sama

Sheet 1_Calon_Pelanggan
A1: 📋 Daftar CALON pelanggan (belum tentu terpasang). Jika sudah Terpasang & punya ID Pelanggan, catat lengkap di sheet "2_Data_Pelanggan".
A3: no | B3: Nama Pelanggan | C3: Nomor Telepon | D3: NO LAPORAN | E3: Alamat Pemasangan | F3: Jadwal Pasang | G3: Jenis Layanan | H3: Status | I3: marketing
A4: =IF($B4="","",COUNTA($B$4:$B4)) -> 1 | B4: tanti setya ningsih | C4: 082134180021 | D4: PSB15226062302 | E4: karang kemiri,tlaga rt01/rw04 kec.gumelar | G4: Internet 20 Mbps | H4: Belum
A5: =IF($B5="","",COUNTA($B$4:$B5)) -> 2 | B5: suritno | C5: 085742794085 | D5: PSB15226062701 | E5: Palumbungan rt2/rw2 | G5: Internet 20 Mbps | H5: Belum
A6: =IF($B6="","",COUNTA($B$4:$B6)) -> 3 | B6: balaidesa gumelar | D6: PSB15226063005 | G6: Internet 50 Mbps | H6: Belum | I6: pak yusuf
A7: =IF($B7="","",COUNTA($B$4:$B7)) -> 4 | B7: suripno | C7: 085742794085 | D7: PSB15226063006 | E7: gumelar 02/rw02 | G7: Internet 20 Mbps | H7: Belum | I7: pak yusuf
A8: =IF($B8="","",COUNTA($B$4:$B8)) -> 5 | B8: siti solehati | C8: 085258650061 | D8: PSB15226063008 | E8: Gumelar, gang kiri masuk sebelum polsek 07/01 | G8: Internet 20 Mbps | H8: Belum | I8: agan
A9: =IF($B9="","",COUNTA($B$4:$B9)) -> 6 | B9: andre sayur | D9: PSB15226063011 | E9: gumelar rt07/rw01 | G9: Internet 20 Mbps | H9: Belum | I9: pak yusuf
A10: =IF($B10="","",COUNTA($B$4:$B10)) -> 7 | B10: SULIYAH | C10: 085747997069 | D10: PSB15226063014 | E10: Depan SDN cilangkap satria | G10: Internet 20 Mbps | H10: Belum | I10: pak yusuf
A11: =IF($B11="","",COUNTA($B$4:$B11)) -> 8 | B11: KASLAM | C11: 085701908313 | D11: PSB15226070202 | E11: GUMELAR 02/04 | G11: Internet 20 Mbps | H11: Belum
A12: =IF($B12="","",COUNTA($B$4:$B12)) -> 9 | B12: watri | C12: 085643133951 | D12: PSB15226070203 | E12: GUMELAR 02/04 | G12: Internet 20 Mbps | H12: Belum
A13: =IF($B13="","",COUNTA($B$4:$B13)) -> 10 | B13: FIRDOS PRIO GUNAWAN | C13: 085747304136 | D13: PSB15226070501 | E13: Gumelar 003/002 | G13: Internet 20 Mbps | H13: Belum
A14: =IF($B14="","",COUNTA($B$4:$B14)) -> 11 | B14: Jamhari | C14: 081210533307 | D14: PSB15226070502 | E14: Cilangkap 001/001 | G14: Internet 20 Mbps | H14: Belum | J14: https://maps.app.goo.gl/1DiPYcbuNpUPYenS6
A15: =IF($B15="","",COUNTA($B$4:$B15)) -> 12 | B15: RAMINAH | C15: 081226123793 | D15: PSB15226070504 | E15: Gumelar Rt 6/ Rw 1 | G15: Internet 20 Mbps | H15: Belum
A16: =IF($B16="","",COUNTA($B$4:$B16)) -> 13 | B16: DANI ISKANDAR SLAMET | C16: 0882006218144 | D16: PSB15226070505 | E16: Gumelar RT.09 / RW 01 | G16: Internet 20 Mbps | H16: Belum | I16: andono
A17: =IF($B17="","",COUNTA($B$4:$B17)) -> 14 | B17: RIMBOWO | C17: 085600244148 | D17: PSB15226070801 | E17: GUMELAR RT 06/05 | G17: Internet 20 Mbps | H17: Belum
A18: =IF($B18="","",COUNTA($B$4:$B18)) -> 15 | B18: SRIYANTI LESTARI | C18: 085815697840 | D18: PSB15226070802 | E18: GUMELAR RT 08/01 | G18: Internet 20 Mbps | H18: Belum
A19: =IF($B19="","",COUNTA($B$4:$B19)) -> 16 | B19: SALSADILA NAHDIATUL AWALIYAH | C19: 81228624907 | D19: PSB15226070901 | E19: GUMELAR RT 6/9 | G19: Internet 50 Mbps
A20: =IF($B20="","",COUNTA($B$4:$B20))
A21: =IF($B21="","",COUNTA($B$4:$B21))
A22: =IF($B22="","",COUNTA($B$4:$B22))
A23: =IF($B23="","",COUNTA($B$4:$B23))
A24: =IF($B24="","",COUNTA($B$4:$B24))
A25: =IF($B25="","",COUNTA($B$4:$B25))
A26: =IF($B26="","",COUNTA($B$4:$B26))
A27: =IF($B27="","",COUNTA($B$4:$B27))
A28: =IF($B28="","",COUNTA($B$4:$B28))
A29: =IF($B29="","",COUNTA($B$4:$B29))
A30: =IF($B30="","",COUNTA($B$4:$B30))
A31: =IF($B31="","",COUNTA($B$4:$B31))
... A59: =IF($B59="","",COUNTA($B$4:$B59))

Sheet 2_Data_Pelanggan
A1: SHEET MASTER — acuan utama seluruh pelanggan aktif. Lihat sheet "0_Panduan" untuk detail alur data.
A3: NO | B3: ID BARU | C3: ID LAMA | D3: NAMA | E3: NIK KTP | F3: No.HP | G3: Kec | H3: Desa | I3: RW | J3: RT | K3: Kota/Kab | L3: Produk ID | M3: Paket | N3: Harga | O3: IP | P3: Perangkat ID | Q3: SN | R3: ODP | S3: Tgl Aktif | T3: Panjang Kabel | U3: PON OLT | V3: Keterangan | W3: Status | X3: Link Foto | Y3: Link Maps | Z3: WA - Konfirmasi RT/RW | AA3: WA - Umum | AB3: WA - Invoice Tagihan | AC3: WA - Foto/Lokasi | AD3: SSID | AE3: Password WiFi | AF3: VLAN | AG3: Tipe ONU | AH3: Jatuh Tempo Bulan Ini | AI3: WA - Ingatkan (H-3) | AJ3: WA - Jatuh Tempo Hari Ini | AK3: WA - Lewat Tempo | AL3: Tagihan Bln-1 (Pro-rata) | AM3: WA - Invoice Pelanggan Baru | AN3: Port OLT | AO3: Index OLT | AP3: Profile | AQ3: VLAN OLT | AR3: Redaman (dBm) | AS3: SN Lama | AT3: Teknisi Pasang
A5: =IF($D5="","",COUNTA($D$5:$D5)) -> 1 | B5: =IF($D5="","","ARM-"&TEXT(COUNTA($D$5:$D5),"0000")) -> ARM-0001 | C5: G-15226030001 | D5: KANTOR | G5: Gumelar | K5: Banyumas | L5: AR-6 | M5: =IFERROR(VLOOKUP(L5, '4_Produk'!C:E, 2, FALSE()), "") -> 100 | N5: =IFERROR(VLOOKUP(L5, '4_Produk'!C:E, 3, FALSE()), "") -> 330000 | O5: 10.152.2.2 | T5: 3 | U5: 1/1/8:2 | V5: FREE | W5: Aktif | Z5: =IF($F5="","",HYPERLINK("https://wa.me/62"&MID($F5,2,LEN($F5)-1)&"?text="&SUBSTITUTE(SUBSTITUTE("Selamat "&IF(HOUR(NOW())<11,"Pagi",IF(HOUR(NOW())<15,"Siang",IF(HOUR(NOW())<18,"Sore","Malam")))&" Bapak/Ibu "&$D5&","&CHAR(10)&CHAR(10)&"Mohon maaf mengganggu waktunya. Saya dari Tim Teknis Armedia Net wilayah Gumelar ingin melakukan konfirmasi data pelanggan."&CHAR(10)&CHAR(10)&"ID Pelanggan: "&$B5&CHAR(10)&"Boleh dibantu konfirmasi RT/RW rumahnya?"&CHAR(10)&"RT: "&CHAR(10)&"RW: "&CHAR(10)&CHAR(10)&"Terima kasih banyak sebelumnya atas kerjasamanya.",CHAR(10),"%0A")," ","%20"),"Chat WA")) | AA5: =IF($F5="","",HYPERLINK("https://wa.me/62"&MID($F5,2,LEN($F5)-1),"Chat WA")) | AB5: =IF($F5="","",HYPERLINK("https://wa.me/62"&MID($F5,2,LEN($F5)-1)&"?text="&SUBSTITUTE(SUBSTITUTE("📄 *INVOICE TAGIHAN INTERNET*"&CHAR(10)&"ARMEDIA NET - Gumelar"&CHAR(10)&CHAR(10)&"No. Invoice: "&$B5&"/"&CHOOSE(MONTH(NOW()),"JAN","FEB","MAR","APR","MEI","JUN","JUL","AGU","SEP","OKT","NOV","DES")&YEAR(NOW())&CHAR(10)&"Tanggal: "&TEXT(NOW(),"DD/MM/YYYY")&CHAR(10)&CHAR(10)&"Pelanggan: "&$D5&CHAR(10)&"ID Pelanggan: "&$B5&CHAR(10)&CHAR(10)&"Rincian:"&CHAR(10)&"Paket Internet "&$M5&" Mbps"&CHAR(10)&"Rp"&TEXT($N5,"#,##0")&CHAR(10)&CHAR(10)&"TOTAL TAGIHAN: Rp"&TEXT($N5,"#,##0")&CHAR(10)&CHAR(10)&"Periode: "&CHOOSE(MONTH(NOW()),"Januari","Februari","Maret","April","Mei","Juni","Juli","Agustus","September","Oktober","November","Desember")&" "&YEAR(NOW())&CHAR(10)&CHAR(10)&"Mohon lakukan pembayaran dan konfirmasi setelah transfer. Terima kasih atas kerjasamanya."&CHAR(10)&CHAR(10)&"ARMEDIA NET - Gumelar",CHAR(10),"%0A")," ","%20"),"Kirim Invoice")) | AC5: =IF($F5="","",HYPERLINK("https://wa.me/62"&MID($F5,2,LEN($F5)-1)&"?text="&SUBSTITUTE(SUBSTITUTE("Selamat "&IF(HOUR(NOW())<11,"Pagi",IF(HOUR(NOW())<15,"Siang",IF(HOUR(NOW())<18,"Sore","Malam")))&" Bapak/Ibu "&$D5&","&CHAR(10)&CHAR(10)&"Mohon maaf mengganggu waktunya. Kami sedang melengkapi dokumentasi data pelanggan ARMEDIA Net."&CHAR(10)&CHAR(10)&"ID Pelanggan: "&$B5&CHAR(10)&"Mohon bantuannya kirim foto rumah tampak depan, dan share lokasi Google Maps rumahnya."&CHAR(10)&CHAR(10)&"Terima kasih banyak atas kerjasamanya.",CHAR(10),"%0A")," ","%20"),"Chat WA")) | AD5: =IFERROR(VLOOKUP($Q5,'12_ONT_NEW'!$D:$G,4,FALSE()),"") | AH5: =IFERROR(IF($S5="","",DATE(YEAR(TODAY()),MONTH(TODAY()),DAY($S5))),"") | AI5: =IF($F5="","",HYPERLINK("https://wa.me/62"&MID($F5,2,LEN($F5)-1)&"?text="&SUBSTITUTE(SUBSTITUTE("Halo, mengingatkan tagihan yang akan jatuh tempo dalam beberapa hari 🙏"&CHAR(10)&CHAR(10)&"Yth. Bapak/Ibu "&$D5&CHAR(10)&CHAR(10)&"Invoice tagihan internet ARMEDIA Net:"&CHAR(10)&CHAR(10)&"ID Pelanggan: "&$B5&CHAR(10)&"No. Invoice: "&$B5&"-"&TEXT(TODAY(),"yymmdd")&CHAR(10)&"Layanan: Internet "&$M5&" Mbps"&CHAR(10)&"Harga Paket: Rp"&TEXT($N5,"#,##0")&CHAR(10)&"Periode: 1 Bulan"&CHAR(10)&"Jatuh Tempo: "&IF($AH5="","(tgl pasang belum diisi)",TEXT($AH5,"DD-")&CHOOSE(MONTH(TODAY()),"Jan","Feb","Mar","Apr","Mei","Jun","Jul","Agu","Sep","Okt","Nov","Des")&TEXT($AH5,"-YYYY"))&CHAR(10)&CHAR(10)&"Total Tagihan: Rp"&TEXT($N5,"#,##0")&CHAR(10)&CHAR(10)&"Pembayaran transfer ke:"&CHAR(10)&"Bank Mandiri"&CHAR(10)&"006-001-460711-7"&CHAR(10)&"a.n PT AKSES ARTHA MEDIA"&CHAR(10)&CHAR(10)&"Atau bayar tunai ke kantor ARMEDIA Net, Gumelar."&CHAR(10)&"Konfirmasi setelah transfer ya. Terima kasih."&CHAR(10)&CHAR(10)&"Salam, ARMEDIA Net - Gumelar",CHAR(10),"%0A")," ","%20"),"Kirim WA")) | AJ5: =IF($F5="","",HYPERLINK("https://wa.me/62"&MID($F5,2,LEN($F5)-1)&"?text="&SUBSTITUTE(SUBSTITUTE("Halo, tagihan internet Anda jatuh tempo HARI INI ya 🗓"&CHAR(10)&CHAR(10)&"Yth. Bapak/Ibu "&$D5&CHAR(10)&CHAR(10)&"Invoice tagihan internet ARMEDIA Net:"&CHAR(10)&CHAR(10)&"ID Pelanggan: "&$B5&CHAR(10)&"No. Invoice: "&$B5&"-"&TEXT(TODAY(),"yymmdd")&CHAR(10)&"Layanan: Internet "&$M5&" Mbps"&CHAR(10)&"Harga Paket: Rp"&TEXT($N5,"#,##0")&CHAR(10)&"Periode: 1 Bulan"&CHAR(10)&"Jatuh Tempo: "&IF($AH5="","(tgl pasang belum diisi)",TEXT($AH5,"DD-")&CHOOSE(MONTH(TODAY()),"Jan","Feb","Mar","Apr","Mei","Jun","Jul","Agu","Sep","Okt","Nov","Des")&TEXT($AH5,"-YYYY"))&CHAR(10)&CHAR(10)&"Total Tagihan: Rp"&TEXT($N5,"#,##0")&CHAR(10)&CHAR(10)&"Pembayaran transfer ke:"&CHAR(10)&"Bank Mandiri"&CHAR(10)&"006-001-460711-7"&CHAR(10)&"a.n PT AKSES ARTHA MEDIA"&CHAR(10)&CHAR(10)&"Atau bayar tunai ke kantor ARMEDIA Net, Gumelar."&CHAR(10)&"Konfirmasi setelah transfer ya. Terima kasih."&CHAR(10)&CHAR(10)&"Salam, ARMEDIA Net - Gumelar",CHAR(10),"%0A")," ","%20"),"Kirim WA")) | AK5: =IF($F5="","",HYPERLINK("https://wa.me/62"&MID($F5,2,LEN($F5)-1)&"?text="&SUBSTITUTE(SUBSTITUTE("Halo, tagihan internet Anda sudah MELEWATI jatuh tempo. Mohon segera diselesaikan agar layanan tidak terputus 🙏"&CHAR(10)&CHAR(10)&"Yth. Bapak/Ibu "&$D5&CHAR(10)&CHAR(10)&"Invoice tagihan internet ARMEDIA Net:"&CHAR(10)&CHAR(10)&"ID Pelanggan: "&$B5&CHAR(10)&"No. Invoice: "&$B5&"-"&TEXT(TODAY(),"yymmdd")&CHAR(10)&"Layanan: Internet "&$M5&" Mbps"&CHAR(10)&"Harga Paket: Rp"&TEXT($N5,"#,##0")&CHAR(10)&"Periode: 1 Bulan"&CHAR(10)&"Jatuh Tempo: "&IF($AH5="","(tgl pasang belum diisi)",TEXT($AH5,"DD-")&CHOOSE(MONTH(TODAY()),"Jan","Feb","Mar","Apr","Mei","Jun","Jul","Agu","Sep","Okt","Nov","Des")&TEXT($AH5,"-YYYY"))&CHAR(10)&CHAR(10)&"Total Tagihan: Rp"&TEXT($N5,"#,##0")&CHAR(10)&CHAR(10)&"Pembayaran transfer ke:"&CHAR(10)&"Bank Mandiri"&CHAR(10)&"006-001-460711-7"&CHAR(10)&"a.n PT AKSES ARTHA MEDIA"&CHAR(10)&CHAR(10)&"Atau bayar tunai ke kantor ARMEDIA Net, Gumelar."&CHAR(10)&"Konfirmasi setelah transfer ya. Terima kasih."&CHAR(10)&CHAR(10)&"Salam, ARMEDIA Net - Gumelar",CHAR(10),"%0A")," ","%20"),"Kirim WA")) | AL5: =IFERROR(IF(OR($S5="",$N5=""),"",ROUND((30-DAY($S5))*$N5/30,0)),"") | AM5: =IF($F5="","",HYPERLINK("https://wa.me/62"&MID($F5,2,LEN($F5)-1)&"?text="&SUBSTITUTE(SUBSTITUTE("Selamat datang di ARMEDIA Net, Bapak/Ibu "&$D5&"!"&CHAR(10)&CHAR(10)&"Terima kasih sudah bergabung. Berikut invoice TAGIHAN PERTAMA Anda:"&CHAR(10)&CHAR(10)&"ID Pelanggan: "&$B5&CHAR(10)&"Layanan: Internet "&$M5&" Mbps"&CHAR(10)&"Harga Normal: Rp"&TEXT($N5,"#,##0")&"/bulan"&CHAR(10)&"Tanggal Pasang: "&IF($S5="","-",TEXT($S5,"DD ")&CHOOSE(MONTH(TODAY()),"Jan","Feb","Mar","Apr","Mei","Jun","Jul","Agu","Sep","Okt","Nov","Des")&TEXT($S5,"-YYYY"))&CHAR(10)&CHAR(10)&"TAGIHAN BULAN PERTAMA (pro-rata):"&CHAR(10)&"Rp"&IF($AL5="","-",TEXT($AL5,"#,##0"))&CHAR(10)&CHAR(10)&"Kenapa beda dari harga normal? Karena tagihan bulan pertama dihitung dari tanggal pasang (bukan awal bulan). Bulan berikutnya sudah normal Rp"&TEXT($N5,"#,##0")&"."&CHAR(10)&CHAR(10)&"Pembayaran transfer ke:"&CHAR(10)&"Bank Mandiri"&CHAR(10)&"006-001-460711-7"&CHAR(10)&"a.n PT AKSES ARTHA MEDIA"&CHAR(10)&CHAR(10)&"Atau tunai ke kantor ARMEDIA Net, Gumelar."&CHAR(10)&"Konfirmasi setelah transfer ya. Terima kasih!"&CHAR(10)&CHAR(10)&"Salam, ARMEDIA Net - Gumelar",CHAR(10),"%0A")," ","%20"),"Kirim Invoice")) | AP5: =IF($M5="","",IFERROR(LOOKUP(9999,--LEFT($M5,ROW(INDIRECT("1:"&LEN($M5)))))&"M_UP","")) -> 1M_UP | AQ5: 1521
A6: =IF($D6="","",COUNTA($D$5:$D6)) -> 2 | B6: =IF($D6="","","ARM-"&TEXT(COUNTA($D$5:$D6),"0000")) -> ARM-0002 | C6: G-15226030002 | D6: PERTASHOP | G6: Gumelar | K6: Banyumas | L6: AR-4 | M6: =IFERROR(VLOOKUP(L6, '4_Produk'!C:E, 2, FALSE()), "") -> 50 | N6: =IFERROR(VLOOKUP(L6, '4_Produk'!C:E, 3, FALSE()), "") -> 182000 | O6: 10.152.3.2 | P6: PG-1522602026 | Q6: HWTC072EFD8F | T6: 10 | U6: 1/1/8:1 | V6: FREE | W6: Aktif | Z6: =IF($F6="","",HYPERLINK("https://wa.me/62"&MID($F6,2,LEN($F6)-1)&"?text="&SUBSTITUTE(SUBSTITUTE("Selamat "&IF(HOUR(NOW())<11,"Pagi",IF(HOUR(NOW())<15,"Siang",IF(HOUR(NOW())<18,"Sore","Malam")))&" Bapak/Ibu "&$D6&","&CHAR(10)&CHAR(10)&"Mohon maaf mengganggu waktunya. Saya dari Tim Teknis Armedia Net wilayah Gumelar ingin melakukan konfirmasi data pelanggan."&CHAR(10)&CHAR(10)&"ID Pelanggan: "&$B6&CHAR(10)&"Boleh dibantu konfirmasi RT/RW rumahnya?"&CHAR(10)&"RT: "&CHAR(10)&"RW: "&CHAR(10)&CHAR(10)&"Terima kasih banyak sebelumnya atas kerjasamanya.",CHAR(10),"%0A")," ","%20"),"Chat WA")) | AA6: =IF($F6="","",HYPERLINK("https://wa.me/62"&MID($F6,2,LEN($F6)-1),"Chat WA")) | AB6: =IF($F6="","",HYPERLINK("https://wa.me/62"&MID($F6,2,LEN($F6)-1)&"?text="&SUBSTITUTE(SUBSTITUTE("📄 *INVOICE TAGIHAN INTERNET*"&CHAR(10)&"ARMEDIA NET - Gumelar"&CHAR(10)&CHAR(10)&"No. Invoice: "&$B6&"/"&CHOOSE(MONTH(NOW()),"JAN","FEB","MAR","APR","MEI","JUN","JUL","AGU","SEP","OKT","NOV","DES")&YEAR(NOW())&CHAR(10)&"Tanggal: "&TEXT(NOW(),"DD/MM/YYYY")&CHAR(10)&CHAR(10)&"Pelanggan: "&$D6&CHAR(10)&"ID Pelanggan: "&$B6&CHAR(10)&CHAR(10)&"Rincian:"&CHAR(10)&"Paket Internet "&$M6&" Mbps"&CHAR(10)&"Rp"&TEXT($N6,"#,##0")&CHAR(10)&CHAR(10)&"TOTAL TAGIHAN: Rp"&TEXT($N6,"#,##0")&CHAR(10)&CHAR(10)&"Periode: "&CHOOSE(MONTH(NOW()),"Januari","Februari","Maret","April","Mei","Juni","Juli","Agustus","September","Oktober","November","Desember")&" "&YEAR(NOW())&CHAR(10)&CHAR(10)&"Mohon lakukan pembayaran dan konfirmasi setelah transfer. Terima kasih atas kerjasamanya."&CHAR(10)&CHAR(10)&"ARMEDIA NET - Gumelar",CHAR(10),"%0A")," ","%20"),"Kirim Invoice")) | AC6: =IF($F6="","",HYPERLINK("https://wa.me/62"&MID($F6,2,LEN($F6)-1)&"?text="&SUBSTITUTE(SUBSTITUTE("Selamat "&IF(HOUR(NOW())<11,"Pagi",IF(HOUR(NOW())<15,"Siang",IF(HOUR(NOW())<18,"Sore","Malam")))&" Bapak/Ibu "&$D6&","&CHAR(10)&CHAR(10)&"Mohon maaf mengganggu waktunya. Kami sedang melengkapi dokumentasi data pelanggan ARMEDIA Net."&CHAR(10)&CHAR(10)&"ID Pelanggan: "&$B6&CHAR(10)&"Mohon bantuannya kirim foto rumah tampak depan, dan share lokasi Google Maps rumahnya."&CHAR(10)&CHAR(10)&"Terima kasih banyak atas kerjasamanya.",CHAR(10),"%0A")," ","%20"),"Chat WA")) | AD6: =IFERROR(VLOOKUP($Q6,'12_ONT_NEW'!$D:$G,4,FALSE()),"") | AH6: =IFERROR(IF($S6="","",DATE(YEAR(TODAY()),MONTH(TODAY()),DAY($S6))),"") | AI6: =IF($F6="","",HYPERLINK("https://wa.me/62"&MID($F6,2,LEN($F6)-1)&"?text="&SUBSTITUTE(SUBSTITUTE("Halo, mengingatkan tagihan yang akan jatuh tempo dalam beberapa hari 🙏"&CHAR(10)&CHAR(10)&"Yth. Bapak/Ibu "&$D6&CHAR(10)&CHAR(10)&"Invoice tagihan internet ARMEDIA Net:"&CHAR(10)&CHAR(10)&"ID Pelanggan: "&$B6&CHAR(10)&"No. Invoice: "&$B6&"-"&TEXT(TODAY(),"yymmdd")&CHAR(10)&"Layanan: Internet "&$M6&" Mbps"&CHAR(10)&"Harga Paket: Rp"&TEXT($N6,"#,##0")&CHAR(10)&"Periode: 1 Bulan"&CHAR(10)&"Jatuh Tempo: "&IF($AH6="","(tgl pasang belum diisi)",TEXT($AH6,"DD-")&CHOOSE(MONTH(TODAY()),"Jan","Feb","Mar","Apr","Mei","Jun","Jul","Agu","Sep","Okt","Nov","Des")&TEXT($AH6,"-YYYY"))&CHAR(10)&CHAR(10)&"Total Tagihan: Rp"&TEXT($N6,"#,##0")&CHAR(10)&CHAR(10)&"Pembayaran transfer ke:"&CHAR(10)&"Bank Mandiri"&CHAR(10)&"006-001-460711-7"&CHAR(10)&"a.n PT AKSES ARTHA MEDIA"&CHAR(10)&CHAR(10)&"Atau bayar tunai ke kantor ARMEDIA Net, Gumelar."&CHAR(10)&"Konfirmasi setelah transfer ya. Terima kasih."&CHAR(10)&CHAR(10)&"Salam, ARMEDIA Net - Gumelar",CHAR(10),"%0A")," ","%20"),"Kirim WA")) | AJ6: =IF($F6="","",HYPERLINK("https://wa.me/62"&MID($F6,2,LEN($F6)-1)&"?text="&SUBSTITUTE(SUBSTITUTE("Halo, tagihan internet Anda jatuh tempo HARI INI ya 🗓"&CHAR(10)&CHAR(10)&"Yth. Bapak/Ibu "&$D6&CHAR(10)&CHAR(10)&"Invoice tagihan internet ARMEDIA Net:"&CHAR(10)&CHAR(10)&"ID Pelanggan: "&$B6&CHAR(10)&"No. Invoice: "&$B6&"-"&TEXT(TODAY(),"yymmdd")&CHAR(10)&"Layanan: Internet "&$M6&" Mbps"&CHAR(10)&"Harga Paket: Rp"&TEXT($N6,"#,##0")&CHAR(10)&"Periode: 1 Bulan"&CHAR(10)&"Jatuh Tempo: "&IF($AH6="","(tgl pasang belum diisi)",TEXT($AH6,"DD-")&CHOOSE(MONTH(TODAY()),"Jan","Feb","Mar","Apr","Mei","Jun","Jul","Agu","Sep","Okt","Nov","Des")&TEXT($AH6,"-YYYY"))&CHAR(10)&CHAR(10)&"Total Tagihan: Rp"&TEXT($N6,"#,##0")&CHAR(10)&CHAR(10)&"Pembayaran transfer ke:"&CHAR(10)&"Bank Mandiri"&CHAR(10)&"006-001-460711-7"&CHAR(10)&"a.n PT AKSES ARTHA MEDIA"&CHAR(10)&CHAR(10)&"Atau bayar tunai ke kantor ARMEDIA Net, Gumelar."&CHAR(10)&"Konfirmasi setelah transfer ya. Terima kasih."&CHAR(10)&CHAR(10)&"Salam, ARMEDIA Net - Gumelar",CHAR(10),"%0A")," ","%20"),"Kirim WA")) | AK6: =IF($F6="","",HYPERLINK("https://wa.me/62"&MID($F6,2,LEN($F6)-1)&"?text="&SUBSTITUTE(SUBSTITUTE("Halo, tagihan internet Anda sudah MELEWATI jatuh tempo. Mohon segera diselesaikan agar layanan tidak terputus 🙏"&CHAR(10)&CHAR(10)&"Yth. Bapak/Ibu "&$D6&CHAR(10)&CHAR(10)&"Invoice tagihan internet ARMEDIA Net:"&CHAR(10)&CHAR(10)&"ID Pelanggan: "&$B6&CHAR(10)&"No. Invoice: "&$B6&"-"&TEXT(TODAY(),"yymmdd")&CHAR(10)&"Layanan: Internet "&$M6&" Mbps"&CHAR(10)&"Harga Paket: Rp"&TEXT($N6,"#,##0")&CHAR(10)&"Periode: 1 Bulan"&CHAR(10)&"Jatuh Tempo: "&IF($AH6="","(tgl pasang belum diisi)",TEXT($AH6,"DD-")&CHOOSE(MONTH(TODAY()),"Jan","Feb","Mar","Apr","Mei","Jun","Jul","Agu","Sep","Okt","Nov","Des")&TEXT($AH6,"-YYYY"))&CHAR(10)&CHAR(10)&"Total Tagihan: Rp"&TEXT($N6,"#,##0")&CHAR(10)&CHAR(10)&"Pembayaran transfer ke:"&CHAR(10)&"Bank Mandiri"&CHAR(10)&"006-001-460711-7"&CHAR(10)&"a.n PT AKSES ARTHA MEDIA"&CHAR(10)&CHAR(10)&"Atau bayar tunai ke kantor ARMEDIA Net, Gumelar."&CHAR(10)&"Konfirmasi setelah transfer ya. Terima kasih."&CHAR(10)&CHAR(10)&"Salam, ARMEDIA Net - Gumelar",CHAR(10),"%0A")," ","%20"),"Kirim WA")) | AL6: =IFERROR(IF(OR($S6="",$N6=""),"",ROUND((30-DAY($S6))*$N6/30,0)),"") | AM6: =IF($F6="","",HYPERLINK("https://wa.me/62"&MID($F6,2,LEN($F6)-1)&"?text="&SUBSTITUTE(SUBSTITUTE("Selamat datang di ARMEDIA Net, Bapak/Ibu "&$D6&"!"&CHAR(10)&CHAR(10)&"Terima kasih sudah bergabung. Berikut invoice TAGIHAN PERTAMA Anda:"&CHAR(10)&CHAR(10)&"ID Pelanggan: "&$B6&CHAR(10)&"Layanan: Internet "&$M6&" Mbps"&CHAR(10)&"Harga Normal: Rp"&TEXT($N6,"#,##0")&"/bulan"&CHAR(10)&"Tanggal Pasang: "&IF($S6="","-",TEXT($S6,"DD ")&CHOOSE(MONTH(TODAY()),"Jan","Feb","Mar","Apr","Mei","Jun","Jul","Agu","Sep","Okt","Nov","Des")&TEXT($S6,"-YYYY"))&CHAR(10)&CHAR(10)&"TAGIHAN BULAN PERTAMA (pro-rata):"&CHAR(10)&"Rp"&IF($AL6="","-",TEXT($AL6,"#,##0"))&CHAR(10)&CHAR(10)&"Kenapa beda dari harga normal? Karena tagihan bulan pertama dihitung dari tanggal pasang (bukan awal bulan). Bulan berikutnya sudah normal Rp"&TEXT($N6,"#,##0")&"."&CHAR(10)&CHAR(10)&"Pembayaran transfer ke:"&CHAR(10)&"Bank Mandiri"&CHAR(10)&"006-001-460711-7"&CHAR(10)&"a.n PT AKSES ARTHA MEDIA"&CHAR(10)&CHAR(10)&"Atau tunai ke kantor ARMEDIA Net, Gumelar."&CHAR(10)&"Konfirmasi setelah transfer ya. Terima kasih!"&CHAR(10)&CHAR(10)&"Salam, ARMEDIA Net - Gumelar",CHAR(10),"%0A")," ","%20"),"Kirim Invoice")) | AP6: =IF($M6="","",IFERROR(LOOKUP(9999,--LEFT($M6,ROW(INDIRECT("1:"&LEN($M6)))))&"M_UP","")) -> 5M_UP | AQ6: 1521
A7: =IF($D7="","",COUNTA($D$5:$D7)) -> 3 | B7: =IF($D7="","","ARM-"&TEXT(COUNTA($D$5:$D7),"0000")) -> ARM-0003 | C7: G-15226031001 | D7: JUNO | E7: 3302150207710002 | F7: 081391345444 | G7: Gumelar | H7: CIHONJE | I7: 5 | J7: 2 | K7: Banyumas | L7: AR-3 | M7: =IFERROR(VLOOKUP(L7, '4_Produk'!C:E, 2, FALSE()), "") -> 30 | N7: =IFERROR(VLOOKUP(L7, '4_Produk'!C:E, 3, FALSE()), "") -> 142000 | O7: 10.152.7.246 | P7: PG-1522602001 | Q7: HWTC072EC10F | S7: 46091 | T7: 70 | U7: 1/1/3:1 | V7: FREE | W7: Aktif | Z7: =IF($F7="","",HYPERLINK("https://wa.me/62"&MID($F7,2,LEN($F7)-1)&"?text="&SUBSTITUTE(SUBSTITUTE("Selamat "&IF(HOUR(NOW())<11,"Pagi",IF(HOUR(NOW())<15,"Siang",IF(HOUR(NOW())<18,"Sore","Malam")))&" Bapak/Ibu "&$D7&","&CHAR(10)&CHAR(10)&"Mohon maaf mengganggu waktunya. Saya dari Tim Teknis Armedia Net wilayah Gumelar ingin melakukan konfirmasi data pelanggan."&CHAR(10)&CHAR(10)&"ID Pelanggan: "&$B7&CHAR(10)&"Boleh dibantu konfirmasi RT/RW rumahnya?"&CHAR(10)&"RT: "&CHAR(10)&"RW: "&CHAR(10)&CHAR(10)&"Terima kasih banyak sebelumnya atas kerjasamanya.",CHAR(10),"%0A")," ","%20"),"Chat WA")) -> Chat WA | AA7: =IF($F7="","",HYPERLINK("https://wa.me/62"&MID($F7,2,LEN($F7)-1),"Chat WA")) -> Chat WA | AB7: =IF($F7="","",HYPERLINK("https://wa.me/62"&MID($F7,2,LEN($F7)-1)&"?text="&SUBSTITUTE(SUBSTITUTE("📄 *INVOICE TAGIHAN INTERNET*"&CHAR(10)&"ARMEDIA NET - Gumelar"&CHAR(10)&CHAR(10)&"No. Invoice: "&$B7&"/"&CHOOSE(MONTH(NOW()),"JAN","FEB","MAR","APR","MEI","JUN","JUL","AGU","SEP","OKT","NOV","DES")&YEAR(NOW())&CHAR(10)&"Tanggal: "&TEXT(NOW(),"DD/MM/YYYY")&CHAR(10)&CHAR(10)&"Pelanggan: "&$D7&CHAR(10)&"ID Pelanggan: "&$B7&CHAR(10)&CHAR(10)&"Rincian:"&CHAR(10)&"Paket Internet "&$M7&" Mbps"&CHAR(10)&"Rp"&TEXT($N7,"#,##0")&CHAR(10)&CHAR(10)&"TOTAL TAGIHAN: Rp"&TEXT($N7,"#,##0")&CHAR(10)&CHAR(10)&"Periode: "&CHOOSE(MONTH(NOW()),"Januari","Februari","Maret","April","Mei","Juni","Juli","Agustus","September","Oktober","November","Desember")&" "&YEAR(NOW())&CHAR(10)&CHAR(10)&"Mohon lakukan pembayaran dan konfirmasi setelah transfer. Terima kasih atas kerjasamanya."&CHAR(10)&CHAR(10)&"ARMEDIA NET - Gumelar",CHAR(10),"%0A")," ","%20"),"Kirim Invoice")) -> Kirim Invoice | AC7: =IF($F7="","",HYPERLINK("https://wa.me/62"&MID($F7,2,LEN($F7)-1)&"?text="&SUBSTITUTE(SUBSTITUTE("Selamat "&IF(HOUR(NOW())<11,"Pagi",IF(HOUR(NOW())<15,"Siang",IF(HOUR(NOW())<18,"Sore","Malam")))&" Bapak/Ibu "&$D7&","&CHAR(10)&CHAR(10)&"Mohon maaf mengganggu waktunya. Kami sedang melengkapi dokumentasi data pelanggan ARMEDIA Net."&CHAR(10)&CHAR(10)&"ID Pelanggan: "&$B7&CHAR(10)&"Mohon bantuannya kirim foto rumah tampak depan, dan share lokasi Google Maps rumahnya."&CHAR(10)&CHAR(10)&"Terima kasih banyak atas kerjasamanya.",CHAR(10),"%0A")," ","%20"),"Chat WA")) -> Chat WA | AD7: =IFERROR(VLOOKUP($Q7,'12_ONT_NEW'!$D:$G,4,FALSE()),"") | AH7: =IFERROR(IF($S7="","",DATE(YEAR(TODAY()),MONTH(TODAY()),DAY($S7))),"") -> 46213 | AI7: =IF($F7="","",HYPERLINK("https://wa.me/62"&MID($F7,2,LEN($F7)-1)&"?text="&SUBSTITUTE(SUBSTITUTE("Halo, mengingatkan tagihan yang akan jatuh tempo dalam beberapa hari 🙏"&CHAR(10)&CHAR(10)&"Yth. Bapak/Ibu "&$D7&CHAR(10)&CHAR(10)&"Invoice tagihan internet ARMEDIA Net:"&CHAR(10)&CHAR(10)&"ID Pelanggan: "&$B7&CHAR(10)&"No. Invoice: "&$B7&"-"&TEXT(TODAY(),"yymmdd")&CHAR(10)&"Layanan: Internet "&$M7&" Mbps"&CHAR(10)&"Harga Paket: Rp"&TEXT($N7,"#,##0")&CHAR(10)&"Periode: 1 Bulan"&CHAR(10)&"Jatuh Tempo: "&IF($AH7="","(tgl pasang belum diisi)",TEXT($AH7,"DD-")&CHOOSE(MONTH(TODAY()),"Jan","Feb","Mar","Apr","Mei","Jun","Jul","Agu","Sep","Okt","Nov","Des")&TEXT($AH7,"-YYYY"))&CHAR(10)&CHAR(10)&"Total Tagihan: Rp"&TEXT($N7,"#,##0")&CHAR(10)&CHAR(10)&"Pembayaran transfer ke:"&CHAR(10)&"Bank Mandiri"&CHAR(10)&"006-001-460711-7"&CHAR(10)&"a.n PT AKSES ARTHA MEDIA"&CHAR(10)&CHAR(10)&"Atau bayar tunai ke kantor ARMEDIA Net, Gumelar."&CHAR(10)&"Konfirmasi setelah transfer ya. Terima kasih."&CHAR(10)&CHAR(10)&"Salam, ARMEDIA Net - Gumelar",CHAR(10),"%0A")," ","%20"),"Kirim WA")) -> Kirim WA | AJ7: =IF($F7="","",HYPERLINK("https://wa.me/62"&MID($F7,2,LEN($F7)-1)&"?text="&SUBSTITUTE(SUBSTITUTE("Halo, tagihan internet Anda jatuh tempo HARI INI ya 🗓"&CHAR(10)&CHAR(10)&"Yth. Bapak/Ibu "&$D7&CHAR(10)&CHAR(10)&"Invoice tagihan internet ARMEDIA Net:"&CHAR(10)&CHAR(10)&"ID Pelanggan: "&$B7&CHAR(10)&"No. Invoice: "&$B7&"-"&TEXT(TODAY(),"yymmdd")&CHAR(10)&"Layanan: Internet "&$M7&" Mbps"&CHAR(10)&"Harga Paket: Rp"&TEXT($N7,"#,##0")&CHAR(10)&"Periode: 1 Bulan"&CHAR(10)&"Jatuh Tempo: "&IF($AH7="","(tgl pasang belum diisi)",TEXT($AH7,"DD-")&CHOOSE(MONTH(TODAY()),"Jan","Feb","Mar","Apr","Mei","Jun","Jul","Agu","Sep","Okt","Nov","Des")&TEXT($AH7,"-YYYY"))&CHAR(10)&CHAR(10)&"Total Tagihan: Rp"&TEXT($N7,"#,##0")&CHAR(10)&CHAR(10)&"Pembayaran transfer ke:"&CHAR(10)&"Bank Mandiri"&CHAR(10)&"006-001-460711-7"&CHAR(10)&"a.n PT AKSES ARTHA MEDIA"&CHAR(10)&CHAR(10)&"Atau bayar tunai ke kantor ARMEDIA Net, Gumelar."&CHAR(10)&"Konfirmasi setelah transfer ya. Terima kasih."&CHAR(10)&CHAR(10)&"Salam, ARMEDIA Net - Gumelar",CHAR(10),"%0A")," ","%20"),"Kirim WA")) -> Kirim WA | AK7: =IF($F7="","",HYPERLINK("https://wa.me/62"&MID($F7,2,LEN($F7)-1)&"?text="&SUBSTITUTE(SUBSTITUTE("Halo, tagihan internet Anda sudah MELEWATI jatuh tempo. Mohon segera diselesaikan agar layanan tidak terputus 🙏"&CHAR(10)&CHAR(10)&"Yth. Bapak/Ibu "&$D7&CHAR(10)&CHAR(10)&"Invoice tagihan internet ARMEDIA Net:"&CHAR(10)&CHAR(10)&"ID Pelanggan: "&$B7&CHAR(10)&"No. Invoice: "&$B7&"-"&TEXT(TODAY(),"yymmdd")&CHAR(10)&"Layanan: Internet "&$M7&" Mbps"&CHAR(10)&"Harga Paket: Rp"&TEXT($N7,"#,##0")&CHAR(10)&"Periode: 1 Bulan"&CHAR(10)&"Jatuh Tempo: "&IF($AH7="","(tgl pasang belum diisi)",TEXT($AH7,"DD-")&CHOOSE(MONTH(TODAY()),"Jan","Feb","Mar","Apr","Mei","Jun","Jul","Agu","Sep","Okt","Nov","Des")&TEXT($AH7,"-YYYY"))&CHAR(10)&CHAR(10)&"Total Tagihan: Rp"&TEXT($N7,"#,##0")&CHAR(10)&CHAR(10)&"Pembayaran transfer ke:"&CHAR(10)&"Bank Mandiri"&CHAR(10)&"006-001-460711-7"&CHAR(10)&"a.n PT AKSES ARTHA MEDIA"&CHAR(10)&CHAR(10)&"Atau bayar tunai ke kantor ARMEDIA Net, Gumelar."&CHAR(10)&"Konfirmasi setelah transfer ya. Terima kasih."&CHAR(10)&CHAR(10)&"Salam, ARMEDIA Net - Gumelar",CHAR(10),"%0A")," ","%20"),"Kirim WA")) -> Kirim WA | AL7: =IFERROR(IF(OR($S7="",$N7=""),"",ROUND((30-DAY($S7))*$N7/30,0)),"") -> 94667 | AM7: =IF($F7="","",HYPERLINK("https://wa.me/62"&MID($F7,2,LEN($F7)-1)&"?text="&SUBSTITUTE(SUBSTITUTE("Selamat datang di ARMEDIA Net, Bapak/Ibu "&$D7&"!"&CHAR(10)&CHAR(10)&"Terima kasih sudah bergabung. Berikut invoice TAGIHAN PERTAMA Anda:"&CHAR(10)&CHAR(10)&"ID Pelanggan: "&$B7&CHAR(10)&"Layanan: Internet "&$M7&" Mbps"&CHAR(10)&"Harga Normal: Rp"&TEXT($N7,"#,##0")&"/bulan"&CHAR(10)&"Tanggal Pasang: "&IF($S7="","-",TEXT($S7,"DD ")&CHOOSE(MONTH(TODAY()),"Jan","Feb","Mar","Apr","Mei","Jun","Jul","Agu","Sep","Okt","Nov","Des")&TEXT($S7,"-YYYY"))&CHAR(10)&CHAR(10)&"TAGIHAN BULAN PERTAMA (pro-rata):"&CHAR(10)&"Rp"&IF($AL7="","-",TEXT($AL7,"#,##0"))&CHAR(10)&CHAR(10)&"Kenapa beda dari harga normal? Karena tagihan bulan pertama dihitung dari tanggal pasang (bukan awal bulan). Bulan berikutnya sudah normal Rp"&TEXT($N7,"#,##0")&"."&CHAR(10)&CHAR(10)&"Pembayaran transfer ke:"&CHAR(10)&"Bank Mandiri"&CHAR(10)&"006-001-460711-7"&CHAR(10)&"a.n PT AKSES ARTHA MEDIA"&CHAR(10)&CHAR(10)&"Atau tunai ke kantor ARMEDIA Net, Gumelar."&CHAR(10)&"Konfirmasi setelah transfer ya. Terima kasih!"&CHAR(10)&CHAR(10)&"Salam, ARMEDIA Net - Gumelar",CHAR(10),"%0A")," ","%20"),"Kirim Invoice")) -> Kirim Invoice | AP7: =IF($M7="","",IFERROR(LOOKUP(9999,--LEFT($M7,ROW(INDIRECT("1:"&LEN($M7)))))&"M_UP","")) -> 3M_UP | AQ7: 1521
A8: =IF($D8="","",COUNTA($D$5:$D8)) -> 4 | B8: =IF($D8="","","ARM-"&TEXT(COUNTA($D$5:$D8),"0000")) -> ARM-0004 | C8: G-15226031501 | D8: TAMIRAH | E8: 3302154902770003 | F8: 081210984891 | G8: Gumelar | H8: CIHONJE | I8: 4 | J8: 3 | K8: Banyumas | L8: AR-2 | M8: =IFERROR(VLOOKUP(L8, '4_Produk'!C:E, 2, FALSE()), "") -> 20 | N8: =IFERROR(VLOOKUP(L8, '4_Produk'!C:E, 3, FALSE()), "") -> 115000 | O8: 10.152.6.30 | P8: PG-1522602002 | Q8: HWTC072EB97F | S8: 46096 | T8: 100 | U8: 1/1/3:2 | W8: Aktif | Z8: =IF($F8="","",HYPERLINK("https://wa.me/62"&MID($F8,2,LEN($F8)-1)&"?text="&SUBSTITUTE(SUBSTITUTE("Selamat "&IF(HOUR(NOW())<11,"Pagi",IF(HOUR(NOW())<15,"Siang",IF(HOUR(NOW())<18,"Sore","Malam")))&" Bapak/Ibu "&$D8&","&CHAR(10)&CHAR(10)&"Mohon maaf mengganggu waktunya. Saya dari Tim Teknis Armedia Net wilayah Gumelar ingin melakukan konfirmasi data pelanggan."&CHAR(10)&CHAR(10)&"ID Pelanggan: "&$B8&CHAR(10)&"Boleh dibantu konfirmasi RT/RW rumahnya?"&CHAR(10)&"RT: "&CHAR(10)&"RW: "&CHAR(10)&CHAR(10)&"Terima kasih banyak sebelumnya atas kerjasamanya.",CHAR(10),"%0A")," ","%20"),"Chat WA")) -> Chat WA | AA8: =IF($F8="","",HYPERLINK("https://wa.me/62"&MID($F8,2,LEN($F8)-1),"Chat WA")) -> Chat WA | AB8: =IF($F8="","",HYPERLINK("https://wa.me/62"&MID($F8,2,LEN($F8)-1)&"?text="&SUBSTITUTE(SUBSTITUTE("📄 *INVOICE TAGIHAN INTERNET*"&CHAR(10)&"ARMEDIA NET - Gumelar"&CHAR(10)&CHAR(10)&"No. Invoice: "&$B8&"/"&CHOOSE(MONTH(NOW()),"JAN","FEB","MAR","APR","MEI","JUN","JUL","AGU","SEP","OKT","NOV","DES")&YEAR(NOW())&CHAR(10)&"Tanggal: "&TEXT(NOW(),"DD/MM/YYYY")&CHAR(10)&CHAR(10)&"Pelanggan: "&$D8&CHAR(10)&"ID Pelanggan: "&$B8&CHAR(10)&CHAR(10)&"Rincian:"&CHAR(10)&"Paket Internet "&$M8&" Mbps"&CHAR(10)&"Rp"&TEXT($N8,"#,##0")&CHAR(10)&CHAR(10)&"TOTAL TAGIHAN: Rp"&TEXT($N8,"#,##0")&CHAR(10)&CHAR(10)&"Periode: "&CHOOSE(MONTH(NOW()),"Januari","Februari","Maret","April","Mei","Juni","Juli","Agustus","September","Oktober","November","Desember")&" "&YEAR(NOW())&CHAR(10)&CHAR(10)&"Mohon lakukan pembayaran dan konfirmasi setelah transfer. Terima kasih atas kerjasamanya."&CHAR(10)&CHAR(10)&"ARMEDIA NET - Gumelar",CHAR(10),"%0A")," ","%20"),"Kirim Invoice")) -> Kirim Invoice | AC8: =IF($F8="","",HYPERLINK("https://wa.me/62"&MID($F8,2,LEN($F8)-1)&"?text="&SUBSTITUTE(SUBSTITUTE("Selamat "&IF(HOUR(NOW())<11,"Pagi",IF(HOUR(NOW())<15,"Siang",IF(HOUR(NOW())<18,"Sore","Malam")))&" Bapak/Ibu "&$D8&","&CHAR(10)&CHAR(10)&"Mohon maaf mengganggu waktunya. Kami sedang melengkapi dokumentasi data pelanggan ARMEDIA Net."&CHAR(10)&CHAR(10)&"ID Pelanggan: "&$B8&CHAR(10)&"Mohon bantuannya kirim foto rumah tampak depan, dan share lokasi Google Maps rumahnya."&CHAR(10)&CHAR(10)&"Terima kasih banyak atas kerjasamanya.",CHAR(10),"%0A")," ","%20"),"Chat WA")) -> Chat WA | AD8: =IFERROR(VLOOKUP($Q8,'12_ONT_NEW'!$D:$G,4,FALSE()),"") | AH8: =IFERROR(IF($S8="","",DATE(YEAR(TODAY()),MONTH(TODAY()),DAY($S8))),"") -> 46218 | AI8: =IF($F8="","",HYPERLINK("https://wa.me/62"&MID($F8,2,LEN($F8)-1)&"?text="&SUBSTITUTE(SUBSTITUTE("Halo, mengingatkan tagihan yang akan jatuh tempo dalam beberapa hari 🙏"&CHAR(10)&CHAR(10)&"Yth. Bapak/Ibu "&$D8&CHAR(10)&CHAR(10)&"Invoice tagihan internet ARMEDIA Net:"&CHAR(10)&CHAR(10)&"ID Pelanggan: "&$B8&CHAR(10)&"No. Invoice: "&$B8&"-"&TEXT(TODAY(),"yymmdd")&CHAR(10)&"Layanan: Internet "&$M8&" Mbps"&CHAR(10)&"Harga Paket: Rp"&TEXT($N8,"#,##0")&CHAR(10)&"Periode: 1 Bulan"&CHAR(10)&"Jatuh Tempo: "&IF($AH8="","(tgl pasang belum diisi)",TEXT($AH8,"DD-")&CHOOSE(MONTH(TODAY()),"Jan","Feb","Mar","Apr","Mei","Jun","Jul","Agu","Sep","Okt","Nov","Des")&TEXT($AH8,"-YYYY"))&CHAR(10)&CHAR(10)&"Total Tagihan: Rp"&TEXT($N8,"#,##0")&CHAR(10)&CHAR(10)&"Pembayaran transfer ke:"&CHAR(10)&"Bank Mandiri"&CHAR(10)&"006-001-460711-7"&CHAR(10)&"a.n PT AKSES ARTHA MEDIA"&CHAR(10)&CHAR(10)&"Atau bayar tunai ke kantor ARMEDIA Net, Gumelar."&CHAR(10)&"Konfirmasi setelah transfer ya. Terima kasih."&CHAR(10)&CHAR(10)&"Salam, ARMEDIA Net - Gumelar",CHAR(10),"%0A")," ","%20"),"Kirim WA")) -> Kirim WA | AJ8: =IF($F8="","",HYPERLINK("https://wa.me/62"&MID($F8,2,LEN($F8)-1)&"?text="&SUBSTITUTE(SUBSTITUTE("Halo, tagihan internet Anda jatuh tempo HARI INI ya 🗓"&CHAR(10)&CHAR(10)&"Yth. Bapak/Ibu "&$D8&CHAR(10)&CHAR(10)&"Invoice tagihan internet ARMEDIA Net:"&CHAR(10)&CHAR(10)&"ID Pelanggan: "&$B8&CHAR(10)&"No. Invoice: "&$B8&"-"&TEXT(TODAY(),"yymmdd")&CHAR(10)&"Layanan: Internet "&$M8&" Mbps"&CHAR(10)&"Harga Paket: Rp"&TEXT($N8,"#,##0")&CHAR(10)&"Periode: 1 Bulan"&CHAR(10)&"Jatuh Tempo: "&IF($AH8="","(tgl pasang belum diisi)",TEXT($AH8,"DD-")&CHOOSE(MONTH(TODAY()),"Jan","Feb","Mar","Apr","Mei","Jun","Jul","Agu","Sep","Okt","Nov","Des")&TEXT($AH8,"-YYYY"))&CHAR(10)&CHAR(10)&"Total Tagihan: Rp"&TEXT($N8,"#,##0")&CHAR(10)&CHAR(10)&"Pembayaran transfer ke:"&CHAR(10)&"Bank Mandiri"&CHAR(10)&"006-001-460711-7"&CHAR(10)&"a.n PT AKSES ARTHA MEDIA"&CHAR(10)&CHAR(10)&"Atau bayar tunai ke kantor ARMEDIA Net, Gumelar."&CHAR(10)&"Konfirmasi setelah transfer ya. Terima kasih."&CHAR(10)&CHAR(10)&"Salam, ARMEDIA Net - Gumelar",CHAR(10),"%0A")," ","%20"),"Kirim WA")) -> Kirim WA | AK8: =IF($F8="","",HYPERLINK("https://wa.me/62"&MID($F8,2,LEN($F8)-1)&"?text="&SUBSTITUTE(SUBSTITUTE("Halo, tagihan internet Anda sudah MELEWATI jatuh tempo. Mohon segera diselesaikan agar layanan tidak terputus 🙏"&CHAR(10)&CHAR(10)&"Yth. Bapak/Ibu "&$D8&CHAR(10)&CHAR(10)&"Invoice tagihan internet ARMEDIA Net:"&CHAR(10)&CHAR(10)&"ID Pelanggan: "&$B8&CHAR(10)&"No. Invoice: "&$B8&"-"&TEXT(TODAY(),"yymmdd")&CHAR(10)&"Layanan: Internet "&$M8&" Mbps"&CHAR(10)&"Harga Paket: Rp"&TEXT($N8,"#,##0")&CHAR(10)&"Periode: 1 Bulan"&CHAR(10)&"Jatuh Tempo: "&IF($AH8="","(tgl pasang belum diisi)",TEXT($AH8,"DD-")&CHOOSE(MONTH(TODAY()),"Jan","Feb","Mar","Apr","Mei","Jun","Jul","Agu","Sep","Okt","Nov","Des")&TEXT($AH8,"-YYYY"))&CHAR(10)&CHAR(10)&"Total Tagihan: Rp"&TEXT($N8,"#,##0")&CHAR(10)&CHAR(10)&"Pembayaran transfer ke:"&CHAR(10)&"Bank Mandiri"&CHAR(10)&"006-001-460711-7"&CHAR(10)&"a.n PT AKSES ARTHA MEDIA"&CHAR(10)&CHAR(10)&"Atau bayar tunai ke kantor ARMEDIA Net, Gumelar."&CHAR(10)&"Konfirmasi setelah transfer ya. Terima kasih."&CHAR(10)&CHAR(10)&"Salam, ARMEDIA Net - Gumelar",CHAR(10),"%0A")," ","%20"),"Kirim WA")) -> Kirim WA | AL8: =IFERROR(IF(OR($S8="",$N8=""),"",ROUND((30-DAY($S8))*$N8/30,0)),"") -> 57500 | AM8: =IF($F8="","",HYPERLINK("https://wa.me/62"&MID($F8,2,LEN($F8)-1)&"?text="&SUBSTITUTE(SUBSTITUTE("Selamat datang di ARMEDIA Net, Bapak/Ibu "&$D8&"!"&CHAR(10)&CHAR(10)&"Terima kasih sudah bergabung. Berikut invoice TAGIHAN PERTAMA Anda:"&CHAR(10)&CHAR(10)&"ID Pelanggan: "&$B8&CHAR(10)&"Layanan: Internet "&$M8&" Mbps"&CHAR(10)&"Harga Normal: Rp"&TEXT($N8,"#,##0")&"/bulan"&CHAR(10)&"Tanggal Pasang: "&IF($S8="","-",TEXT($S8,"DD ")&CHOOSE(MONTH(TODAY()),"Jan","Feb","Mar","Apr","Mei","Jun","Jul","Agu","Sep","Okt","Nov","Des")&TEXT($S8,"-YYYY"))&CHAR(10)&CHAR(10)&"TAGIHAN BULAN PERTAMA (pro-rata):"&CHAR(10)&"Rp"&IF($AL8="","-",TEXT($AL8,"#,##0"))&CHAR(10)&CHAR(10)&"Kenapa beda dari harga normal? Karena tagihan bulan pertama dihitung dari tanggal pasang (bukan awal bulan). Bulan berikutnya sudah normal Rp"&TEXT($N8,"#,##0")&"."&CHAR(10)&CHAR(10)&"Pembayaran transfer ke:"&CHAR(10)&"Bank Mandiri"&CHAR(10)&"006-001-460711-7"&CHAR(10)&"a.n PT AKSES ARTHA MEDIA"&CHAR(10)&CHAR(10)&"Atau tunai ke kantor ARMEDIA Net, Gumelar."&CHAR(10)&"Konfirmasi setelah transfer ya. Terima kasih!"&CHAR(10)&CHAR(10)&"Salam, ARMEDIA Net - Gumelar",CHAR(10),"%0A")," ","%20"),"Kirim Invoice")) -> Kirim Invoice | AP8: =IF($M8="","",IFERROR(LOOKUP(9999,--LEFT($M8,ROW(INDIRECT("1:"&LEN($M8)))))&"M_UP","")) -> 2M_UP | AQ8: 1521
A9: =IF($D9="","",COUNTA($D$5:$D9)) -> 5 | B9: =IF($D9="","","ARM-"&TEXT(COUNTA($D$5:$D9),"0000")) -> ARM-0005 | C9: G-15226031502 | D9: SARWO | F9: 085718161841 | G9: Gumelar | H9: CIHONJE | K9: Banyumas | L9: AR-3 | M9: =IFERROR(VLOOKUP(L9, '4_Produk'!C:E, 2, FALSE()), "") -> 30 | N9: =IFERROR(VLOOKUP(L9, '4_Produk'!C:E, 3, FALSE()), "") -> 142000 | O9: 10.152.5.6 | P9: PG-1522602003 | Q9: ZXIC074F370F | S9: 46096 | T9: 50 | U9: 1/1/7:1 | V9: FREE | W9: Aktif | Z9: =IF($F9="","",HYPERLINK("https://wa.me/62"&MID($F9,2,LEN($F9)-1)&"?text="&SUBSTITUTE(SUBSTITUTE("Selamat "&IF(HOUR(NOW())<11,"Pagi",IF(HOUR(NOW())<15,"Siang",IF(HOUR(NOW())<18,"Sore","Malam")))&" Bapak/Ibu "&$D9&","&CHAR(10)&CHAR(10)&"Mohon maaf mengganggu waktunya. Saya dari Tim Teknis Armedia Net wilayah Gumelar ingin melakukan konfirmasi data pelanggan."&CHAR(10)&CHAR(10)&"ID Pelanggan: "&$B9&CHAR(10)&"Boleh dibantu konfirmasi RT/RW rumahnya?"&CHAR(10)&"RT: "&CHAR(10)&"RW: "&CHAR(10)&CHAR(10)&"Terima kasih banyak sebelumnya atas kerjasamanya.",CHAR(10),"%0A")," ","%20"),"Chat WA")) -> Chat WA | AA9: =IF($F9="","",HYPERLINK("https://wa.me/62"&MID($F9,2,LEN($F9)-1),"Chat WA")) -> Chat WA | AB9: =IF($F9="","",HYPERLINK("https://wa.me/62"&MID($F9,2,LEN($F9)-1)&"?text="&SUBSTITUTE(SUBSTITUTE("📄 *INVOICE TAGIHAN INTERNET*"&CHAR(10)&"ARMEDIA NET - Gumelar"&CHAR(10)&CHAR(10)&"No. Invoice: "&$B9&"/"&CHOOSE(MONTH(NOW()),"JAN","FEB","MAR","APR","MEI","JUN","JUL","AGU","SEP","OKT","NOV","DES")&YEAR(NOW())&CHAR(10)&"Tanggal: "&TEXT(NOW(),"DD/MM/YYYY")&CHAR(10)&CHAR(10)&"Pelanggan: "&$D9&CHAR(10)&"ID Pelanggan: "&$B9&CHAR(10)&CHAR(10)&"Rincian:"&CHAR(10)&"Paket Internet "&$M9&" Mbps"&CHAR(10)&"Rp"&TEXT($N9,"#,##0")&CHAR(10)&CHAR(10)&"TOTAL TAGIHAN: Rp"&TEXT($N9,"#,##0")&CHAR(10)&CHAR(10)&"Periode: "&CHOOSE(MONTH(NOW()),"Januari","Februari","Maret","April","Mei","Juni","Juli","Agustus","September","Oktober","November","Desember")&" "&YEAR(NOW())&CHAR(10)&CHAR(10)&"Mohon lakukan pembayaran dan konfirmasi setelah transfer. Terima kasih atas kerjasamanya."&CHAR(10)&CHAR(10)&"ARMEDIA NET - Gumelar",CHAR(10),"%0A")," ","%20"),"Kirim Invoice")) -> Kirim Invoice | AC9: =IF($F9="","",HYPERLINK("https://wa.me/62"&MID($F9,2,LEN($F9)-1)&"?text="&SUBSTITUTE(SUBSTITUTE("Selamat "&IF(HOUR(NOW())<11,"Pagi",IF(HOUR(NOW())<15,"Siang",IF(HOUR(NOW())<18,"Sore","Malam")))&" Bapak/Ibu "&$D9&","&CHAR(10)&CHAR(10)&"Mohon maaf mengganggu waktunya. Kami sedang melengkapi dokumentasi data pelanggan ARMEDIA Net."&CHAR(10)&CHAR(10)&"ID Pelanggan: "&$B9&CHAR(10)&"Mohon bantuannya kirim foto rumah tampak depan, dan share lokasi Google Maps rumahnya."&CHAR(10)&CHAR(10)&"Terima kasih banyak atas kerjasamanya.",CHAR(10),"%0A")," ","%20"),"Chat WA")) -> Chat WA | AD9: =IFERROR(VLOOKUP($Q9,'12_ONT_NEW'!$D:$G,4,FALSE()),"") -> 5i951g_2.4G | AH9: =IFERROR(IF($S9="","",DATE(YEAR(TODAY()),MONTH(TODAY()),DAY($S9))),"") -> 46218 | AI9: =IF($F9="","",HYPERLINK("https://wa.me/62"&MID($F9,2,LEN($F9)-1)&"?text="&SUBSTITUTE(SUBSTITUTE("Halo, mengingatkan tagihan yang akan jatuh tempo dalam beberapa hari 🙏"&CHAR(10)&CHAR(10)&"Yth. Bapak/Ibu "&$D9&CHAR(10)&CHAR(10)&"Invoice tagihan internet ARMEDIA Net:"&CHAR(10)&CHAR(10)&"ID Pelanggan: "&$B9&CHAR(10)&"No. Invoice: "&$B9&"-"&TEXT(TODAY(),"yymmdd")&CHAR(10)&"Layanan: Internet "&$M9&" Mbps"&CHAR(10)&"Harga Paket: Rp"&TEXT($N9,"#,##0")&CHAR(10)&"Periode: 1 Bulan"&CHAR(10)&"Jatuh Tempo: "&IF($AH9="","(tgl pasang belum diisi)",TEXT($AH9,"DD-")&CHOOSE(MONTH(TODAY()),"Jan","Feb","Mar","Apr","Mei","Jun","Jul","Agu","Sep","Okt","Nov","Des")&TEXT($AH9,"-YYYY"))&CHAR(10)&CHAR(10)&"Total Tagihan: Rp"&TEXT($N9,"#,##0")&CHAR(10)&CHAR(10)&"Pembayaran transfer ke:"&CHAR(10)&"Bank Mandiri"&CHAR(10)&"006-001-460711-7"&CHAR(10)&"a.n PT AKSES ARTHA MEDIA"&CHAR(10)&CHAR(10)&"Atau bayar tunai ke kantor ARMEDIA Net, Gumelar."&CHAR(10)&"Konfirmasi setelah transfer ya. Terima kasih."&CHAR(10)&CHAR(10)&"Salam, ARMEDIA Net - Gumelar",CHAR(10),"%0A")," ","%20"),"Kirim WA")) -> Kirim WA | AJ9: =IF($F9="","",HYPERLINK("https://wa.me/62"&MID($F9,2,LEN($F9)-1)&"?text="&SUBSTITUTE(SUBSTITUTE("Halo, tagihan internet Anda jatuh tempo HARI INI ya 🗓"&CHAR(10)&CHAR(10)&"Yth. Bapak/Ibu "&$D9&CHAR(10)&CHAR(10)&"Invoice tagihan internet ARMEDIA Net:"&CHAR(10)&CHAR(10)&"ID Pelanggan: "&$B9&CHAR(10)&"No. Invoice: "&$B9&"-"&TEXT(TODAY(),"yymmdd")&CHAR(10)&"Layanan: Internet "&$M9&" Mbps"&CHAR(10)&"Harga Paket: Rp"&TEXT($N9,"#,##0")&CHAR(10)&"Periode: 1 Bulan"&CHAR(10)&"Jatuh Tempo: "&IF($AH9="","(tgl pasang belum diisi)",TEXT($AH9,"DD-")&CHOOSE(MONTH(TODAY()),"Jan","Feb","Mar","Apr","Mei","Jun","Jul","Agu","Sep","Okt","Nov","Des")&TEXT($AH9,"-YYYY"))&CHAR(10)&CHAR(10)&"Total Tagihan: Rp"&TEXT($N9,"#,##0")&CHAR(10)&CHAR(10)&"Pembayaran transfer ke:"&CHAR(10)&"Bank Mandiri"&CHAR(10)&"006-001-460711-7"&CHAR(10)&"a.n PT AKSES ARTHA MEDIA"&CHAR(10)&CHAR(10)&"Atau bayar tunai ke kantor ARMEDIA Net, Gumelar."&CHAR(10)&"Konfirmasi setelah transfer ya. Terima kasih."&CHAR(10)&CHAR(10)&"Salam, ARMEDIA Net - Gumelar",CHAR(10),"%0A")," ","%20"),"Kirim WA")) -> Kirim WA | AK9: =IF($F9="","",HYPERLINK("https://wa.me/62"&MID($F9,2,LEN($F9)-1)&"?text="&SUBSTITUTE(SUBSTITUTE("Halo, tagihan internet Anda sudah MELEWATI jatuh tempo. Mohon segera diselesaikan agar layanan tidak terputus 🙏"&CHAR(10)&CHAR(10)&"Yth. Bapak/Ibu "&$D9&CHAR(10)&CHAR(10)&"Invoice tagihan internet ARMEDIA Net:"&CHAR(10)&CHAR(10)&"ID Pelanggan: "&$B9&CHAR(10)&"No. Invoice: "&$B9&"-"&TEXT(TODAY(),"yymmdd")&CHAR(10)&"Layanan: Internet "&$M9&" Mbps"&CHAR(10)&"Harga Paket: Rp"&TEXT($N9,"#,##0")&CHAR(10)&"Periode: 1 Bulan"&CHAR(10)&"Jatuh Tempo: "&IF($AH9="","(tgl pasang belum diisi)",TEXT($AH9,"DD-")&CHOOSE(MONTH(TODAY()),"Jan","Feb","Mar","Apr","Mei","Jun","Jul","Agu","Sep","Okt","Nov","Des")&TEXT($AH9,"-YYYY"))&CHAR(10)&CHAR(10)&"Total Tagihan: Rp"&TEXT($N9,"#,##0")&CHAR(10)&CHAR(10)&"Pembayaran transfer ke:"&CHAR(10)&"Bank Mandiri"&CHAR(10)&"006-001-460711-7"&CHAR(10)&"a.n PT AKSES ARTHA MEDIA"&CHAR(10)&CHAR(10)&"Atau bayar tunai ke kantor ARMEDIA Net, Gumelar."&CHAR(10)&"Konfirmasi setelah transfer ya. Terima kasih."&CHAR(10)&CHAR(10)&"Salam, ARMEDIA Net - Gumelar",CHAR(10),"%0A")," ","%20"),"Kirim WA")) -> Kirim WA | AL9: =IFERROR(IF(OR($S9="",$N9=""),"",ROUND((30-DAY($S9))*$N9/30,0)),"") -> 71000 | AM9: =IF($F9="","",HYPERLINK("https://wa.me/62"&MID($F9,2,LEN($F9)-1)&"?text="&SUBSTITUTE(SUBSTITUTE("Selamat datang di ARMEDIA Net, Bapak/Ibu "&$D9&"!"&CHAR(10)&CHAR(10)&"Terima kasih sudah bergabung. Berikut invoice TAGIHAN PERTAMA Anda:"&CHAR(10)&CHAR(10)&"ID Pelanggan: "&$B9&CHAR(10)&"Layanan: Internet "&$M9&" Mbps"&CHAR(10)&"Harga Normal: Rp"&TEXT($N9,"#,##0")&"/bulan"&CHAR(10)&"Tanggal Pasang: "&IF($S9="","-",TEXT($S9,"DD ")&CHOOSE(MONTH(TODAY()),"Jan","Feb","Mar","Apr","Mei","Jun","Jul","Agu","Sep","Okt","Nov","Des")&TEXT($S9,"-YYYY"))&CHAR(10)&CHAR(10)&"TAGIHAN BULAN PERTAMA (pro-rata):"&CHAR(10)&"Rp"&IF($AL9="","-",TEXT($AL9,"#,##0"))&CHAR(10)&CHAR(10)&"Kenapa beda dari harga normal? Karena tagihan bulan pertama dihitung dari tanggal pasang (bukan awal bulan). Bulan berikutnya sudah normal Rp"&TEXT($N9,"#,##0")&"."&CHAR(10)&CHAR(10)&"Pembayaran transfer ke:"&CHAR(10)&"Bank Mandiri"&CHAR(10)&"006-001-460711-7"&CHAR(10)&"a.n PT AKSES ARTHA MEDIA"&CHAR(10)&CHAR(10)&"Atau tunai ke kantor ARMEDIA Net, Gumelar."&CHAR(10)&"Konfirmasi setelah transfer ya. Terima kasih!"&CHAR(10)&CHAR(10)&"Salam, ARMEDIA Net - Gumelar",CHAR(10),"%0A")," ","%20"),"Kirim Invoice")) -> Kirim Invoice | AP9: =IF($M9="","",IFERROR(LOOKUP(9999,--LEFT($M9,ROW(INDIRECT("1:"&LEN($M9)))))&"M_UP","")) -> 3M_UP | AQ9: 1521
A10: =IF($D10="","",COUNTA($D$5:$D10)) -> 6 | B10: =IF($D10="","","ARM-"&TEXT(COUNTA($D$5:$D10),"0000")) -> ARM-0006 | C10: G-15226031503 | D10: TRIYONO | F10: 089655661661 | G10: Gumelar | H10: CIHONJE | I10: 3 | J10: 2 | K10: Banyumas | L10: AR-2 | M10: =IFERROR(VLOOKUP(L10, '4_Produk'!C:E, 2, FALSE()), "") -> 20 | N10: =IFERROR(VLOOKUP(L10, '4_Produk'!C:E, 3, FALSE()), "") -> 115000 | O10: 10.152.6.6 | P10: PG-1522602004 | Q10: HWTC072EB0EF | S10: 46096 | T10: 50 | U10: 1/1/7:3 | W10: Aktif | Z10: =IF($F10="","",HYPERLINK("https://wa.me/62"&MID($F10,2,LEN($F10)-1)&"?text="&SUBSTITUTE(SUBSTITUTE("Selamat "&IF(HOUR(NOW())<11,"Pagi",IF(HOUR(NOW())<15,"Siang",IF(HOUR(NOW())<18,"Sore","Malam")))&" Bapak/Ibu "&$D10&","&CHAR(10)&CHAR(10)&"Mohon maaf mengganggu waktunya. Saya dari Tim Teknis Armedia Net wilayah Gumelar ingin melakukan konfirmasi data pelanggan."&CHAR(10)&CHAR(10)&"ID Pelanggan: "&$B10&CHAR(10)&"Boleh dibantu konfirmasi RT/RW rumahnya?"&CHAR(10)&"RT: "&CHAR(10)&"RW: "&CHAR(10)&CHAR(10)&"Terima kasih banyak sebelumnya atas kerjasamanya.",CHAR(10),"%0A")," ","%20"),"Chat WA")) -> Chat WA | AA10: =IF($F10="","",HYPERLINK("https://wa.me/62"&MID($F10,2,LEN($F10)-1),"Chat WA")) -> Chat WA | AB10: =IF($F10="","",HYPERLINK("https://wa.me/62"&MID($F10,2,LEN($F10)-1)&"?text="&SUBSTITUTE(SUBSTITUTE("📄 *INVOICE TAGIHAN INTERNET*"&CHAR(10)&"ARMEDIA NET - Gumelar"&CHAR(10)&CHAR(10)&"No. Invoice: "&$B10&"/"&CHOOSE(MONTH(NOW()),"JAN","FEB","MAR","APR","MEI","JUN","JUL","AGU","SEP","OKT","NOV","DES")&YEAR(NOW())&CHAR(10)&"Tanggal: "&TEXT(NOW(),"DD/MM/YYYY")&CHAR(10)&CHAR(10)&"Pelanggan: "&$D10&CHAR(10)&"ID Pelanggan: "&$B10&CHAR(10)&CHAR(10)&"Rincian:"&CHAR(10)&"Paket Internet "&$M10&" Mbps"&CHAR(10)&"Rp"&TEXT($N10,"#,##0")&CHAR(10)&CHAR(10)&"TOTAL TAGIHAN: Rp"&TEXT($N10,"#,##0")&CHAR(10)&CHAR(10)&"Periode: "&CHOOSE(MONTH(NOW()),"Januari","Februari","Maret","April","Mei","Juni","Juli","Agustus","September","Oktober","November","Desember")&" "&YEAR(NOW())&CHAR(10)&CHAR(10)&"Mohon lakukan pembayaran dan konfirmasi setelah transfer. Terima kasih atas kerjasamanya."&CHAR(10)&CHAR(10)&"ARMEDIA NET - Gumelar",CHAR(10),"%0A")," ","%20"),"Kirim Invoice")) -> Kirim Invoice | AC10: =IF($F10="","",HYPERLINK("https://wa.me/62"&MID($F10,2,LEN($F10)-1)&"?text="&SUBSTITUTE(SUBSTITUTE("Selamat "&IF(HOUR(NOW())<11,"Pagi",IF(HOUR(NOW())<15,"Siang",IF(HOUR(NOW())<18,"Sore","Malam")))&" Bapak/Ibu "&$D10&","&CHAR(10)&CHAR(10)&"Mohon maaf mengganggu waktunya. Kami sedang melengkapi dokumentasi data pelanggan ARMEDIA Net."&CHAR(10)&CHAR(10)&"ID Pelanggan: "&$B10&CHAR(10)&"Mohon bantuannya kirim foto rumah tampak depan, dan share lokasi Google Maps rumahnya."&CHAR(10)&CHAR(10)&"Terima kasih banyak atas kerjasamanya.",CHAR(10),"%0A")," ","%20"),"Chat WA")) -> Chat WA | AD10: =IFERROR(VLOOKUP($Q10,'12_ONT_NEW'!$D:$G,4,FALSE()),"") | AH10: =IFERROR(IF($S10="","",DATE(YEAR(TODAY()),MONTH(TODAY()),DAY($S10))),"") -> 46218 | AI10: =IF($F10="","",HYPERLINK("https://wa.me/62"&MID($F10,2,LEN($F10)-1)&"?text="&SUBSTITUTE(SUBSTITUTE("Halo, mengingatkan tagihan yang akan jatuh tempo dalam beberapa hari 🙏"&CHAR(10)&CHAR(10)&"Yth. Bapak/Ibu "&$D10&CHAR(10)&CHAR(10)&"Invoice tagihan internet ARMEDIA Net:"&CHAR(10)&CHAR(10)&"ID Pelanggan: "&$B10&CHAR(10)&"No. Invoice: "&$B10&"-"&TEXT(TODAY(),"yymmdd")&CHAR(10)&"Layanan: Internet "&$M10&" Mbps"&CHAR(10)&"Harga Paket: Rp"&TEXT($N10,"#,##0")&CHAR(10)&"Periode: 1 Bulan"&CHAR(10)&"Jatuh Tempo: "&IF($AH10="","(tgl pasang belum diisi)",TEXT($AH10,"DD-")&CHOOSE(MONTH(TODAY()),"Jan","Feb","Mar","Apr","Mei","Jun","Jul","Agu","Sep","Okt","Nov","Des")&TEXT($AH10,"-YYYY"))&CHAR(10)&CHAR(10)&"Total Tagihan: Rp"&TEXT($N10,"#,##0")&CHAR(10)&CHAR(10)&"Pembayaran transfer ke:"&CHAR(10)&"Bank Mandiri"&CHAR(10)&"006-001-460711-7"&CHAR(10)&"a.n PT AKSES ARTHA MEDIA"&CHAR(10)&CHAR(10)&"Atau bayar tunai ke kantor ARMEDIA Net, Gumelar."&CHAR(10)&"Konfirmasi setelah transfer ya. Terima kasih."&CHAR(10)&CHAR(10)&"Salam, ARMEDIA Net - Gumelar",CHAR(10),"%0A")," ","%20"),"Kirim WA")) -> Kirim WA | AJ10: =IF($F10="","",HYPERLINK("https://wa.me/62"&MID($F10,2,LEN($F10)-1)&"?text="&SUBSTITUTE(SUBSTITUTE("Halo, tagihan internet Anda jatuh tempo HARI INI ya 🗓"&CHAR(10)&CHAR(10)&"Yth. Bapak/Ibu "&$D10&CHAR(10)&CHAR(10)&"Invoice tagihan internet ARMEDIA Net:"&CHAR(10)&CHAR(10)&"ID Pelanggan: "&$B10&CHAR(10)&"No. Invoice: "&$B10&"-"&TEXT(TODAY(),"yymmdd")&CHAR(10)&"Layanan: Internet "&$M10&" Mbps"&CHAR(10)&"Harga Paket: Rp"&TEXT($N10,"#,##0")&CHAR(10)&"Periode: 1 Bulan"&CHAR(10)&"Jatuh Tempo: "&IF($AH10="","(tgl pasang belum diisi)",TEXT($AH10,"DD-")&CHOOSE(MONTH(TODAY()),"Jan","Feb","Mar","Apr","Mei","Jun","Jul","Agu","Sep","Okt","Nov","Des")&TEXT($AH10,"-YYYY"))&CHAR(10)&CHAR(10)&"Total Tagihan: Rp"&TEXT($N10,"#,##0")&CHAR(10)&CHAR(10)&"Pembayaran transfer ke:"&CHAR(10)&"Bank Mandiri"&CHAR(10)&"006-001-460711-7"&CHAR(10)&"a.n PT AKSES ARTHA MEDIA"&CHAR(10)&CHAR(10)&"Atau bayar tunai ke kantor ARMEDIA Net, Gumelar."&CHAR(10)&"Konfirmasi setelah transfer ya. Terima kasih."&CHAR(10)&CHAR(10)&"Salam, ARMEDIA Net - Gumelar",CHAR(10),"%0A")," ","%20"),"Kirim WA")) -> Kirim WA | AK10: =IF($F10="","",HYPERLINK("https://wa.me/62"&MID($F10,2,LEN($F10)-1)&"?text="&SUBSTITUTE(SUBSTITUTE("Halo, tagihan internet Anda sudah MELEWATI jatuh tempo. Mohon segera diselesaikan agar layanan tidak terputus 🙏"&CHAR(10)&CHAR(10)&"Yth. Bapak/Ibu "&$D10&CHAR(10)&CHAR(10)&"Invoice tagihan internet ARMEDIA Net:"&CHAR(10)&CHAR(10)&"ID Pelanggan: "&$B10&CHAR(10)&"No. Invoice: "&$B10&"-"&TEXT(TODAY(),"yymmdd")&CHAR(10)&"Layanan: Internet "&$M10&" Mbps"&CHAR(10)&"Harga Paket: Rp"&TEXT($N10,"#,##0")&CHAR(10)&"Periode: 1 Bulan"&CHAR(10)&"Jatuh Tempo: "&IF($AH10="","(tgl pasang belum diisi)",TEXT($AH10,"DD-")&CHOOSE(MONTH(TODAY()),"Jan","Feb","Mar","Apr","Mei","Jun","Jul","Agu","Sep","Okt","Nov","Des")&TEXT($AH10,"-YYYY"))&CHAR(10)&CHAR(10)&"Total Tagihan: Rp"&TEXT($N10,"#,##0")&CHAR(10)&CHAR(10)&"Pembayaran transfer ke:"&CHAR(10)&"Bank Mandiri"&CHAR(10)&"006-001-460711-7"&CHAR(10)&"a.n PT AKSES ARTHA MEDIA"&CHAR(10)&CHAR(10)&"Atau bayar tunai ke kantor ARMEDIA Net, Gumelar."&CHAR(10)&"Konfirmasi setelah transfer ya. Terima kasih."&CHAR(10)&CHAR(10)&"Salam, ARMEDIA Net - Gumelar",CHAR(10),"%0A")," ","%20"),"Kirim WA")) -> Kirim WA | AL10: =IFERROR(IF(OR($S10="",$N10=""),"",ROUND((30-DAY($S10))*$N10/30,0)),"") -> 57500 | AM10: =IF($F10="","",HYPERLINK("https://wa.me/62"&MID($F10,2,LEN($F10)-1)&"?text="&SUBSTITUTE(SUBSTITUTE("Selamat datang di ARMEDIA Net, Bapak/Ibu "&$D10&"!"&CHAR(10)&CHAR(10)&"Terima kasih sudah bergabung. Berikut invoice TAGIHAN PERTAMA Anda:"&CHAR(10)&CHAR(10)&"ID Pelanggan: "&$B10&CHAR(10)&"Layanan: Internet "&$M10&" Mbps"&CHAR(10)&"Harga Normal: Rp"&TEXT($N10,"#,##0")&"/bulan"&CHAR(10)&"Tanggal Pasang: "&IF($S10="","-",TEXT($S10,"DD ")&CHOOSE(MONTH(TODAY()),"Jan","Feb","Mar","Apr","Mei","Jun","Jul","Agu","Sep","Okt","Nov","Des")&TEXT($S10,"-YYYY"))&CHAR(10)&CHAR(10)&"TAGIHAN BULAN PERTAMA (pro-rata):"&CHAR(10)&"Rp"&IF($AL10="","-",TEXT($AL10,"#,##0"))&CHAR(10)&CHAR(10)&"Kenapa beda dari harga normal? Karena tagihan bulan pertama dihitung dari tanggal pasang (bukan awal bulan). Bulan berikutnya sudah normal Rp"&TEXT($N10,"#,##0")&"."&CHAR(10)&CHAR(10)&"Pembayaran transfer ke:"&CHAR(10)&"Bank Mandiri"&CHAR(10)&"006-001-460711-7"&CHAR(10)&"a.n PT AKSES ARTHA MEDIA"&CHAR(10)&CHAR(10)&"Atau tunai ke kantor ARMEDIA Net, Gumelar."&CHAR(10)&"Konfirmasi setelah transfer ya. Terima kasih!"&CHAR(10)&CHAR(10)&"Salam, ARMEDIA Net - Gumelar",CHAR(10),"%0A")," ","%20"),"Kirim Invoice")) -> Kirim Invoice | AP10: =IF($M10="","",IFERROR(LOOKUP(9999,--LEFT($M10,ROW(INDIRECT("1:"&LEN($M10)))))&"M_UP","")) -> 2M_UP | AQ10: 1521
